<?xml version="1.0" encoding="utf-8"?>
<robot xmlns:xacro="http://ros.org/wiki/xacro">
  <xacro:macro name="thruster_macro" params="name *origin">

    <joint name="${name}_thruster" type="revolute">
      <xacro:insert_block name="origin"/>
      <parent link="base_frame" />
      <child link="${name}" />
        <axis xyz="0 0 1" />
        <limit
          lower="-1E12"
          upper="1E12"
          effort="1E6"
          velocity="100" />
    </joint>

    <link
      name="${name}">
      <inertial>
        <origin xyz="1.29123983e-04 -4.30643335e-05  6.65557479e-04" 
                rpy="0 0 0" />
        <mass value="2.8201033788020022" />
        <inertia
          ixx="1.36253391E-02"
          ixy="-3.62214961E-07"
          ixz="-6.16491988E-07"
          iyy="1.36232618E-02"
          iyz="-9.76544753E-06"
          izz="2.52722006E-02" />
      </inertial>
      <visual>
        <origin
          xyz="0 0 0"
          rpy="0 0 0" />
        <geometry>
          <mesh
            filename="file://$(find rov_ricketts_description)/meshes/propeller.stl" />
        </geometry>
        <material
          name="">
          <color
            rgba="0.5 0.5 0.5 1" />
        </material>
      </visual>
      <collision>
        <origin xyz="0 0 0" rpy="0 0 0" />
        <geometry>
          <mesh
            filename="file://$(find rov_ricketts_description)/meshes/propeller.stl" />
        </geometry>
      </collision>
    </link>

    <gazebo>
      <plugin
        filename="gz-sim-thruster-system"
        name="gz::sim::systems::Thruster">
        <joint_name>${name}_thruster</joint_name>
        <namespace>rov_ricketts</namespace>
        <thrust_coefficient>0.05</thrust_coefficient>
        <fluid_density>1000</fluid_density>
        <propeller_diameter>0.38</propeller_diameter>
        <max_thrust_cmd>10000</max_thrust_cmd>
        <min_thrust_cmd>-10000</min_thrust_cmd>
      </plugin>
    </gazebo>
  
  </xacro:macro>
</robot>